Workbook

Sheet Dados
A1: Link > | B1: PLANILHA para os MEMBROS: QUAIS AS DIFERENÇAS? E FORMAS DE UTILIZAR
A3: Empresa | B3: Código | C3: Atuação | D3: Quantidade total de ações | E3: Valor de mercado | F3: Lucro líquido estimado | G3: P/L projetado | H3: P/L médio (últ. 10 anos) | I3: Desvio do P/L da sua média | J3: CAGR lucros (últ. 5 anos) | K3: Dívida líquida/EBITDA | L3: Lucro por ação estimado | M3: Payout esperado | N3: Dividendo por ação bruto projetado | O3: Dividend Yield bruto estimado | P3: Cotação atual | Q3: Preço Teto | R3: Margem de segurança | S3: Frequência nos anúncios | T3: Meses que costumam anunciar dividendos | U3: Última atualização
A4: Irani | B4: RANI3 | C4: Papel e Celulose | D4: 221172300 | E4: =D4*P4 -> 2012667930 | F4: 215000000 | G4: =P4/L4 -> 9.3612462 | H4: 9.4 | I4: =(G4/H4-1) -> -0.0041227462 | J4: 0.33 | K4: 2.06 | L4: =F4/D4 -> 0.9720928 | M4: 0.7 | N4: =M4*L4 -> 0.68046496 | O4: =N4/P4 -> 0.074776369 | P4: =IFERROR(__xludf.DUMMYFUNCTION("GOOGLEFINANCE(""BVMF:RANI3"")"),9.1) -> 9.1 | Q4: 11 | R4: =1-(P4/Q4) -> 0.17272727 | S4: 5x por ano | T4: mar abr mai ago nov | U4: 46091
A5: Pagbank | B5: PAGS34 | C5: Serviços Financeiros | D5: =279705823*5 -> 1398529115 | E5: =D5*P5 -> 13831452947 | F5: 2550000000 | G5: =P5/L5 -> 5.4240992 | H5: 21.4 | I5: =(G5/H5-1) -> -0.74653742 | J5: 0.158 | K5: 0 | L5: =F5/D5 -> 1.8233442 | M5: 0.4714 | N5: =M5*L5 -> 0.85952447 | O5: =N5/P5 -> 0.08690844 | P5: =IFERROR(__xludf.DUMMYFUNCTION("GOOGLEFINANCE(""BVMF:PAGS34"")"),9.89) -> 9.89 | Q5: =6.5*L5 -> 11.851738 | R5: =1-(P5/Q5) -> 0.1655232 | S5: Trimestral | T5: fev jun set e dez | U5: 46091
A6: CSN Mineração | B6: CMIN3 | C6: Mineração | D6: 5432045700 | E6: =D6*P6 -> 26291101188 | F6: 2500000000 | G6: =P6/L6 -> 10.51644 | H6: 7.8 | I6: =(G6/H6-1) -> 0.3482616 | J6: -0.1125 | K6: -0.69 | L6: =F6/D6 -> 0.46023177 | M6: 0.75 | N6: =M6*L6 -> 0.34517383 | O6: =N6/P6 -> 0.071316906 | P6: =IFERROR(__xludf.DUMMYFUNCTION("GOOGLEFINANCE(""BVMF:CMIN3"")"),4.84) -> 4.84 | Q6: =N6/0.06 -> 5.7528971 | R6: =1-(P6/Q6) -> 0.15868476 | S6: Quadrimestral | T6: abr jul dez | U6: 46091
A7: Vulcabras | B7: VULC3 | C7: Calçados | D7: 312632756 | E7: =D7*P7 -> 5130303526 | F7: 600000000 | G7: =P7/L7 -> 8.5505059 | H7: 9.5 | I7: =(G7/H7-1) -> -0.09994675 | J7: 0.795 | K7: 0.9 | L7: =F7/D7 -> 1.9191847 | M7: 0.5 | N7: =M7*L7 -> 0.95959235 | O7: =N7/P7 -> 0.058476072 | P7: =IFERROR(__xludf.DUMMYFUNCTION("GOOGLEFINANCE(""BVMF:VULC3"")"),16.41) -> 16.41 | Q7: 19.5 | R7: =1-(P7/Q7) -> 0.15846154 | S7: Mensal | T7: jan a dezembro | U7: 46091
A8: Gerdau | B8: GGBR3 | C8: Siderurgia e Metalurgia | D8: 1989711987 | E8: =D8*P8 -> 31119095477 | F8: 3500000000 | G8: =P8/L8 -> 8.8911701 | H8: 10.5 | I8: =(G8/H8-1) -> -0.15322189 | J8: 0.067 | K8: 0.85 | L8: =F8/D8 -> 1.7590486 | M8: 0.65 | N8: =M8*L8 -> 1.1433816 | O8: =N8/P8 -> 0.073106238 | P8: =IFERROR(__xludf.DUMMYFUNCTION("GOOGLEFINANCE(""BVMF:GGBR3"")"),15.64) -> 15.64 | Q8: 18.5 | R8: =1-(P8/Q8) -> 0.15459459 | S8: Trimestral | T8: mar mai ago nov | U8: 46091
A9: Banco BMG | B9: BMGB4 | C9: Bancos | D9: 631845354 | E9: =D9*P9 -> 2988628524 | F9: 600000000 | G9: =P9/L9 -> 4.9810475 | H9: 8.3 | I9: =(G9/H9-1) -> -0.39987379 | J9: 0.0026 | K9: 0 | L9: =F9/D9 -> 0.94959945 | M9: 0.5 | N9: =M9*L9 -> 0.47479972 | O9: =N9/P9 -> 0.10038049 | P9: =IFERROR(__xludf.DUMMYFUNCTION("GOOGLEFINANCE(""BVMF:BMGB4"")"),4.73) -> 4.73 | Q9: =N9/0.085 -> 5.5858791 | R9: =1-(P9/Q9) -> 0.15322192 | S9: Trimestral | T9: abr jul out e dez | U9: 46091
A10: Kepler Weber | B10: KEPL3 | C10: Agronegócio | D10: 173367390 | E10: =D10*P10 -> 1333195229 | F10: 155000000 | G10: =P10/L10 -> 8.6012595 | H10: 9.8 | I10: =(G10/H10-1) -> -0.12232045 | J10: 0.173 | K10: -0.19 | L10: =F10/D10 -> 0.8940551 | M10: 0.6 | N10: =M10*L10 -> 0.53643306 | O10: =N10/P10 -> 0.069757225 | P10: =IFERROR(__xludf.DUMMYFUNCTION("GOOGLEFINANCE(""BVMF:KEPL3"")"),7.69) -> 7.69 | Q10: 9 | R10: =1-(P10/Q10) -> 0.14555556 | S10: Quadrimestral | T10: mar ago e out | U10: 46091
A11: Multiplan | B11: MULT3 | C11: Shoppings | D11: 488678545 | E11: =D11*P11 -> 14621262066 | F11: 1500000000 | G11: =P11/L11 -> 9.747508 | H11: 16 | I11: =(G11/H11-1) -> -0.39078075 | J11: 0.018 | K11: 2.28 | L11: =F11/D11 -> 3.0695025 | M11: 0.5 | N11: =M11*L11 -> 1.5347512 | O11: =N11/P11 -> 0.051295162 | P11: =IFERROR(__xludf.DUMMYFUNCTION("GOOGLEFINANCE(""BVMF:MULT3"")"),29.92) -> 29.92 | Q11: 35 | R11: =1-(P11/Q11) -> 0.14514286 | S11: Quadrimestral | T11: jun set e dez | U11: 46091
A12: Marcopolo | B12: POMO3 | C12: Industrial | D12: 1241439543 | E12: =D12*P12 -> 6852746277 | F12: 1200000000 | G12: =P12/L12 -> 5.7106219 | H12: 10.8 | I12: =(G12/H12-1) -> -0.47123871 | J12: 0.682 | K12: 0.85 | L12: =F12/D12 -> 0.96661977 | M12: 0.5 | N12: =M12*L12 -> 0.48330988 | O12: =N12/P12 -> 0.087556138 | P12: =IFERROR(__xludf.DUMMYFUNCTION("GOOGLEFINANCE(""BVMF:POMO3"")"),5.52) -> 5.52 | Q12: =N12/0.075 -> 6.4441318 | R12: =1-(P12/Q12) -> 0.14340672 | S12: Trimestral | T12: fev mai ago e nov | U12: 46091
A13: IRB | B13: IRBR3 | C13: Seguros | D13: 81843000 | E13: =D13*P13 -> 4529191620 | F13: 670000000 | G13: =P13/L13 -> 6.7599875 | H13: 15.8 | I13: =(G13/H13-1) -> -0.57215269 | J13: 0 | K13: 0 | L13: =F13/D13 -> 8.1864057 | M13: 0.5 | N13: =M13*L13 -> 4.0932028 | O13: =N13/P13 -> 0.073964634 | P13: =IFERROR(__xludf.DUMMYFUNCTION("GOOGLEFINANCE(""BVMF:IRBR3"")"),55.34) -> 55.34 | Q13: 64.55 | R13: =1-(P13/Q13) -> 0.14268009 | S13: Indefinido | T13: Indefinido | U13: 46091
A14: Porto Seguro | B14: PSSA3 | C14: Seguros | D14: 646586060 | E14: =D14*P14 -> 31883158619 | F14: 3700000000 | G14: =P14/L14 -> 8.6170699 | H14: 11 | I14: =(G14/H14-1) -> -0.21663001 | J14: 0.134 | K14: 0 | L14: =F14/D14 -> 5.7223628 | M14: 0.5 | N14: =M14*L14 -> 2.8611814 | O14: =N14/P14 -> 0.058024364 | P14: =IFERROR(__xludf.DUMMYFUNCTION("GOOGLEFINANCE(""BVMF:PSSA3"")"),49.31) -> 49.31 | Q14: =10*L14 -> 57.223628 | R14: =1-(P14/Q14) -> 0.13829301 | S14: Quadrimestral | T14: mar, jun e out | U14: 46091
A15: Klabin | B15: KLBN11 | C15: Papel e Celulose | D15: 1244049145 | E15: =D15*P15 -> 23773779161 | F15: 8600000000 | G15: =P15/L15 -> 2.7643929 | H15: 9.6 | I15: =(G15/H15-1) -> -0.7120424 | J15: 0.1046 | K15: 3.7 | L15: =F15/D15 -> 6.9129102 | M15: 0.15 | N15: =M15*L15 -> 1.0369365 | O15: =N15/P15 -> 0.054261461 | P15: =IFERROR(__xludf.DUMMYFUNCTION("GOOGLEFINANCE(""BVMF:KLBN11"")"),19.11) -> 19.11 | Q15: 22 | R15: =1-(P15/Q15) -> 0.13136364 | S15: Trimestral | T15: fev, mai, ago, nov | U15: 46091
A16: Banco Bradesco | B16: BBDC3 | C16: Bancos | D16: 10597012700 | E16: =D16*P16 -> 174002948534 | F16: 28000000000 | G16: =P16/L16 -> 6.214391 | H16: 9.2 | I16: =(G16/H16-1) -> -0.32452272 | J16: 0.0485 | K16: 0 | L16: =F16/D16 -> 2.6422541 | M16: 0.5 | N16: =M16*L16 -> 1.321127 | O16: =N16/P16 -> 0.080458407 | P16: =IFERROR(__xludf.DUMMYFUNCTION("GOOGLEFINANCE(""BVMF:BBDC3"")"),16.42) -> 16.42 | Q16: =N16/0.07 -> 18.873243 | R16: =1-(P16/Q16) -> 0.12998526 | S16: Semestral | T16: junho e dez | U16: 46091
A17: Klabin | B17: KLBN4 | C17: Papel e Celulose | D17: 6220245728 | E17: =D17*P17 -> 23823541138 | F17: 8600000000 | G17: =P17/L17 -> 2.7701792 | H17: 9.6 | I17: =(G17/H17-1) -> -0.71143967 | J17: 0.1046 | K17: 3.7 | L17: =F17/D17 -> 1.382582 | M17: 0.15 | N17: =M17*L17 -> 0.20738731 | O17: =N17/P17 -> 0.054148122 | P17: =IFERROR(__xludf.DUMMYFUNCTION("GOOGLEFINANCE(""BVMF:KLBN4"")"),3.83) -> 3.83 | Q17: 4.4 | R17: =1-(P17/Q17) -> 0.12954545 | S17: Trimestral | T17: fev, mai, ago, nov | U17: 46091
A18: Klabin | B18: KLBN3 | C18: Papel e Celulose | D18: 6220245728 | E18: =D18*P18 -> 23885743596 | F18: 8600000000 | G18: =P18/L18 -> 2.777412 | H18: 9.6 | I18: =(G18/H18-1) -> -0.71068625 | J18: 0.1046 | K18: 3.7 | L18: =F18/D18 -> 1.382582 | M18: 0.15 | N18: =M18*L18 -> 0.20738731 | O18: =N18/P18 -> 0.054007111 | P18: =IFERROR(__xludf.DUMMYFUNCTION("GOOGLEFINANCE(""BVMF:KLBN3"")"),3.84) -> 3.84 | Q18: 4.4 | R18: =1-(P18/Q18) -> 0.12727273 | S18: Trimestral | T18: fev, mai, ago, nov | U18: 46091
A19: Banco Mercantil | B19: BMEB3 | C19: Bancos | D19: 123728626 | E19: =D19*P19 -> 8751325717 | F19: 1200000000 | G19: =P19/L19 -> 7.2927714 | H19: 6.2 | I19: =(G19/H19-1) -> 0.17625346 | J19: 0.301 | K19: 0 | L19: =F19/D19 -> 9.6986448 | M19: 0.3 | N19: =M19*L19 -> 2.9095935 | O19: =N19/P19 -> 0.041136625 | P19: =IFERROR(__xludf.DUMMYFUNCTION("GOOGLEFINANCE(""BVMF:BMEB3"")"),70.73) -> 70.73 | Q19: 81 | R19: =1-(P19/Q19) -> 0.12679012 | S19: Semestral | T19: fevereiro e ago | U19: 46091
A20: BB Seguridade | B20: BBSE3 | C20: Seguros | D20: 1941214909 | E20: =D20*P20 -> 68039582560 | F20: 8650000000 | G20: =P20/L20 -> 7.8658477 | H20: 12.1 | I20: =(G20/H20-1) -> -0.34992994 | J20: 0.183 | K20: 0 | L20: =F20/D20 -> 4.4559724 | M20: 0.88 | N20: =M20*L20 -> 3.9212557 | O20: =N20/P20 -> 0.11187605 | P20: =IFERROR(__xludf.DUMMYFUNCTION("GOOGLEFINANCE(""BVMF:BBSE3"")"),35.05) -> 35.05 | Q20: 40 | R20: =1-(P20/Q20) -> 0.12375 | S20: Semestral | T20: fevereiro e agosto | U20: 46091
A21: Allos | B21: ALOS3 | C21: Shoppings | D21: 499180780 | E21: =D21*P21 -> 14436308158 | F21: 1500000000 | G21: =P21/L21 -> 9.6242054 | H21: 14.4 | I21: =(G21/H21-1) -> -0.3316524 | J21: 0.365 | K21: 1.8 | L21: =F21/D21 -> 3.0049234 | M21: 1.158 | N21: =M21*L21 -> 3.4797013 | O21: =N21/P21 -> 0.12032162 | P21: =IFERROR(__xludf.DUMMYFUNCTION("GOOGLEFINANCE(""BVMF:ALOS3"")"),28.92) -> 28.92 | Q21: 33 | R21: =1-(P21/Q21) -> 0.12363636 | S21: Mensal | T21: jan-dez | U21: 46091
A22: Metalúrgica Gerdau | B22: GOAU3 | C22: Siderurgia e Metalurgia | D22: 1324908144 | E22: =D22*P22 -> 10453525256 | F22: 1230000000 | G22: =P22/L22 -> 8.498801 | H22: 8.9 | I22: =(G22/H22-1) -> -0.045078537 | J22: 0.067 | K22: 0.85 | L22: =F22/D22 -> 0.92836625 | M22: 0.6 | N22: =M22*L22 -> 0.55701975 | O22: =N22/P22 -> 0.070598194 | P22: =IFERROR(__xludf.DUMMYFUNCTION("GOOGLEFINANCE(""BVMF:GOAU3"")"),7.89) -> 7.89 | Q22: 9 | R22: =1-(P22/Q22) -> 0.12333333 | S22: Trimestral | T22: mar mai ago nov | U22: 46091
A23: CSU | B23: CSUD3 | C23: Tecnologia | D23: 41280684 | E23: =D23*P23 -> 7.5956459e+08 | F23: 115000000 | G23: =P23/L23 -> 6.6049094 | H23: 10.1 | I23: =(G23/H23-1) -> -0.34604857 | J23: 0.147 | K23: -0.13 | L23: =F23/D23 -> 2.7858066 | M23: 0.5 | N23: =M23*L23 -> 1.3929033 | O23: =N23/P23 -> 0.075701265 | P23: =IFERROR(__xludf.DUMMYFUNCTION("GOOGLEFINANCE(""BVMF:CSUD3"")"),18.4) -> 18.4 | Q23: =7.5*L23 -> 20.893549 | R23: =1-(P23/Q23) -> 0.11934541 | S23: Trimestral | T23: mar abr jun set e dez | U23: 46093
A24: Dexxos | B24: DEXP3 | C24: Industrial | D24: 120961140 | E24: =D24*P24 -> 864872151 | F24: 130000000 | G24: =P24/L24 -> 6.6528627 | H24: 5.9 | I24: =(G24/H24-1) -> 0.12760385 | J24: 0.028 | K24: 0.08 | L24: =F24/D24 -> 1.0747253 | M24: 0.45 | N24: =M24*L24 -> 0.48362639 | O24: =N24/P24 -> 0.067640055 | P24: =IFERROR(__xludf.DUMMYFUNCTION("GOOGLEFINANCE(""BVMF:DEXP3"")"),7.15) -> 7.15 | Q24: 8.1 | R24: =1-(P24/Q24) -> 0.11728395 | S24: Semestral | T24: abril e dezembro | U24: 46091
A25: Banco Banrisul | B25: BRSR6 | C25: Bancos | D25: 408974000 | E25: =D25*P25 -> 6919840080 | F25: 1400000000 | G25: =P25/L25 -> 4.9427429 | H25: 6.5 | I25: =(G25/H25-1) -> -0.23957801 | J25: 0.011 | K25: 0 | L25: =F25/D25 -> 3.4232005 | M25: 0.45 | N25: =M25*L25 -> 1.5404402 | O25: =N25/P25 -> 0.091042566 | P25: =IFERROR(__xludf.DUMMYFUNCTION("GOOGLEFINANCE(""BVMF:BRSR6"")"),16.92) -> 16.92 | Q25: 19.15 | R25: =1-(P25/Q25) -> 0.11644909 | S25: Trimestral | T25: Mar, jun, set, dez | U25: 46091
A26: Tegma | B26: TGMA3 | C26: Logistica | D26: 66003000 | E26: =D26*P26 -> 2075794350 | F26: 220000000 | G26: =P26/L26 -> 9.4354289 | H26: 12.9 | I26: =(G26/H26-1) -> -0.26857141 | J26: 0.307 | K26: -0.35 | L26: =F26/D26 -> 3.3331818 | M26: 0.8 | N26: =M26*L26 -> 2.6665455 | O26: =N26/P26 -> 0.084786819 | P26: =IFERROR(__xludf.DUMMYFUNCTION("GOOGLEFINANCE(""BVMF:TGMA3"")"),31.45) -> 31.45 | Q26: =N26/0.075 -> 35.553939 | R26: =1-(P26/Q26) -> 0.11542854 | S26: Quadrimestral | T26: abr ago e nov | U26: 46091
A27: Banco Mercantil | B27: BMEB4 | C27: Bancos | D27: 123728626 | E27: =D27*P27 -> 9898290080 | F27: 1200000000 | G27: =P27/L27 -> 8.2485751 | H27: 6.2 | I27: =(G27/H27-1) -> 0.33041533 | J27: 0.301 | K27: 0 | L27: =F27/D27 -> 9.6986448 | M27: 0.3 | N27: =M27*L27 -> 2.9095935 | O27: =N27/P27 -> 0.036369918 | P27: =IFERROR(__xludf.DUMMYFUNCTION("GOOGLEFINANCE(""BVMF:BMEB4"")"),80.0) -> 80 | Q27: 90 | R27: =1-(P27/Q27) -> 0.11111111 | S27: Semestral | T27: fevereiro e ago | U27: 46091
A28: Tim | B28: TIMS3 | C28: Telecomunicações | D28: 2420598680 | E28: =D28*P28 -> 64387924888 | F28: 5400000000 | G28: =P28/L28 -> 11.92369 | H28: 14.8 | I28: =(G28/H28-1) -> -0.19434528 | J28: 0.145 | K28: -0.18 | L28: =F28/D28 -> 2.2308531 | M28: 1 | N28: =M28*L28 -> 2.2308531 | O28: =N28/P28 -> 0.083866657 | P28: =IFERROR(__xludf.DUMMYFUNCTION("GOOGLEFINANCE(""BVMF:TIMS3"")"),26.6) -> 26.6 | Q28: =N28/0.075 -> 29.744708 | R28: =1-(P28/Q28) -> 0.10572327 | S28: 5x por ano | T28: mar abr jun set dez | U28: 46091
A29: Wiz | B29: WIZC3 | C29: Seguros | D29: 159907000 | E29: =D29*P29 -> 1434365790 | F29: 200000000 | G29: =P29/L29 -> 7.171829 | H29: 8.6 | I29: =(G29/H29-1) -> -0.1660664 | J29: 0.111 | K29: 0.7 | L29: =F29/D29 -> 1.250727 | M29: 0.5 | N29: =M29*L29 -> 0.62536349 | O29: =N29/P29 -> 0.069717223 | P29: =IFERROR(__xludf.DUMMYFUNCTION("GOOGLEFINANCE(""BVMF:WIZC3"")"),8.97) -> 8.97 | Q29: =8*L29 -> 10.005816 | R29: =1-(P29/Q29) -> 0.10352138 | S29: Anual | T29: abril | U29: 46091
A30: Emae | B30: EMAE4 | C30: Energia | D30: 36947000 | E30: =D30*P30 -> 1644141500 | F30: 200000000 | G30: =P30/L30 -> 8.2207075 | H30: 14.6 | I30: =(G30/H30-1) -> -0.43693784 | J30: 0 | K30: -12.04 | L30: =F30/D30 -> 5.4131594 | M30: 0.4 | N30: =M30*L30 -> 2.1652638 | O30: =N30/P30 -> 0.048657613 | P30: =IFERROR(__xludf.DUMMYFUNCTION("GOOGLEFINANCE(""BVMF:EMAE4"")"),44.5) -> 44.5 | Q30: 49.5 | R30: =1-(P30/Q30) -> 0.1010101 | S30: Anual | T30: abril | U30: 46091
A31: Banco Santander | B31: SANB3 | C31: Bancos | D31: 7470968456 | E31: =D31*P31 -> 111915107471 | F31: 17400000000 | G31: =P31/L31 -> 6.4319027 | H31: 10.2 | I31: =(G31/H31-1) -> -0.3694213 | J31: -0.015 | K31: 0 | L31: =F31/D31 -> 2.3290153 | M31: 0.5 | N31: =M31*L31 -> 1.1645077 | O31: =N31/P31 -> 0.077737494 | P31: =IFERROR(__xludf.DUMMYFUNCTION("GOOGLEFINANCE(""BVMF:SANB3"")"),14.98) -> 14.98 | Q31: =N31/0.07 -> 16.635824 | R31: =1-(P31/Q31) -> 0.099533618 | S31: Trimestral | T31: fev, abr, julho e out | U31: 46091
A32: Banco Banese | B32: BGIP4 | C32: Bancos | D32: 21548228 | E32: =D32*P32 -> 8.1085982e+08 | F32: 150000000 | G32: =P32/L32 -> 5.4057321 | H32: 7.3 | I32: =(G32/H32-1) -> -0.25948875 | J32: 0.22 | K32: 0 | L32: =F32/D32 -> 6.9611292 | M32: 0.45 | N32: =M32*L32 -> 3.1325082 | O32: =N32/P32 -> 0.083244968 | P32: =IFERROR(__xludf.DUMMYFUNCTION("GOOGLEFINANCE(""BVMF:BGIP4"")"),37.63) -> 37.63 | Q32: =N32/0.075 -> 41.766775 | R32: =1-(P32/Q32) -> 0.099044645 | S32: Trimestral | T32: fev maio ago e nov | U32: 46091
A33: Grendene | B33: GRND3 | C33: Calçados | D33: 902160000 | E33: =D33*P33 -> 4095806400 | F33: 600000000 | G33: =P33/L33 -> 6.826344 | H33: 10.9 | I33: =(G33/H33-1) -> -0.37372991 | J33: 0.149 | K33: -2.38 | L33: =F33/D33 -> 0.6650705 | M33: 0.55 | N33: =M33*L33 -> 0.36578877 | O33: =N33/P33 -> 0.080570214 | P33: =IFERROR(__xludf.DUMMYFUNCTION("GOOGLEFINANCE(""BVMF:GRND3"")"),4.54) -> 4.54 | Q33: =5 -> 5 | R33: =1-(P33/Q33) -> 0.092 | S33: Quadrimestral | T33: maio ago e nov | U33: 46091
A34: Banco Santander | B34: SANB11 | C34: Bancos | D34: =7470968456/2 -> 3735484228 | E34: =D34*P34 -> 112886333370 | F34: 17400000000 | G34: =P34/L34 -> 6.4877203 | H34: 10.2 | I34: =(G34/H34-1) -> -0.36394899 | J34: -0.015 | K34: 0 | L34: =F34/D34 -> 4.6580306 | M34: 0.5 | N34: =M34*L34 -> 2.3290153 | O34: =N34/P34 -> 0.077068674 | P34: =IFERROR(__xludf.DUMMYFUNCTION("GOOGLEFINANCE(""BVMF:SANB11"")"),30.22) -> 30.22 | Q34: =N34/0.07 -> 33.271647 | R34: =1-(P34/Q34) -> 0.091719157 | S34: Trimestral | T34: fev, abr, julho e out | U34: 46091
A35: Mahle Metal Leve | B35: LEVE3 | C35: Automóveis e Motocicletas | D35: 135539000 | E35: =D35*P35 -> 4667963160 | F35: 630000000 | G35: =P35/L35 -> 7.4094653 | H35: 11.2 | I35: =(G35/H35-1) -> -0.3384406 | J35: 0.345 | K35: 0.87 | L35: =F35/D35 -> 4.6481087 | M35: 0.65 | N35: =M35*L35 -> 3.0212706 | O35: =N35/P35 -> 0.087725628 | P35: =IFERROR(__xludf.DUMMYFUNCTION("GOOGLEFINANCE(""BVMF:LEVE3"")"),34.44) -> 34.44 | Q35: =N35/0.08 -> 37.765883 | R35: =1-(P35/Q35) -> 0.088065805 | S35: Semestral | T35: abril e nov | U35: 46091
A36: Marcopolo | B36: POMO4 | C36: Industrial | D36: 1241439543 | E36: =D36*P36 -> 7312078908 | F36: 1200000000 | G36: =P36/L36 -> 6.0933991 | H36: 9.7 | I36: =(G36/H36-1) -> -0.37181453 | J36: 0.682 | K36: 0.85 | L36: =F36/D36 -> 0.96661977 | M36: 0.5 | N36: =M36*L36 -> 0.48330988 | O36: =N36/P36 -> 0.082056007 | P36: =IFERROR(__xludf.DUMMYFUNCTION("GOOGLEFINANCE(""BVMF:POMO4"")"),5.89) -> 5.89 | Q36: =N36/0.075 -> 6.4441318 | R36: =1-(P36/Q36) -> 0.085990136 | S36: Trimestral | T36: fev mai ago e nov | U36: 46091
A37: Banco Bradesco | B37: BBDC4 | C37: Bancos | D37: 10597012700 | E37: =D37*P37 -> 201237271173 | F37: 28000000000 | G37: =P37/L37 -> 7.1870454 | H37: 10.1 | I37: =(G37/H37-1) -> -0.28841135 | J37: 0.0118 | K37: 0 | L37: =F37/D37 -> 2.6422541 | M37: 0.55 | N37: =M37*L37 -> 1.4532397 | O37: =N37/P37 -> 0.076526579 | P37: =IFERROR(__xludf.DUMMYFUNCTION("GOOGLEFINANCE(""BVMF:BBDC4"")"),18.99) -> 18.99 | Q37: =N37/0.07 -> 20.760568 | R37: =1-(P37/Q37) -> 0.085285131 | S37: Semestral | T37: junho e dez | U37: 46091
A38: Odontoprev | B38: ODPV3 | C38: Seguros | D38: 545092900 | E38: =D38*P38 -> 7195226280 | F38: 595000000 | G38: =P38/L38 -> 12.092817 | H38: 19.4 | I38: =(G38/H38-1) -> -0.3766589 | J38: 0.1 | K38: -0.64 | L38: =F38/D38 -> 1.0915571 | M38: 0.95 | N38: =M38*L38 -> 1.0369792 | O38: =N38/P38 -> 0.07855903 | P38: =IFERROR(__xludf.DUMMYFUNCTION("GOOGLEFINANCE(""BVMF:ODPV3"")"),13.2) -> 13.2 | Q38: 14.4 | R38: =1-(P38/Q38) -> 0.083333333 | S38: 8x por ano | T38: mar abr mai jun ago set nov dez | U38: 46091
A39: BTG | B39: BPAC11 | C39: Bancos | D39: 11642630400 | E39: =D39*P39/3 -> 213875120448 | F39: 20000000000 | G39: =P39/L39 -> 10.693756 | H39: 17.4 | I39: =(G39/H39-1) -> -0.38541632 | J39: 0.1966 | K39: 0 | L39: =F39*3/D39 -> 5.1534746 | M39: 0.3 | N39: =M39*L39 -> 1.5460424 | O39: =N39/P39 -> 0.028053754 | P39: =IFERROR(__xludf.DUMMYFUNCTION("GOOGLEFINANCE(""BVMF:BPAC11"")"),55.11) -> 55.11 | Q39: 60 | R39: =1-(P39/Q39) -> 0.0815 | S39: Quadrimestral | T39: jan ago e dez | U39: 46091
A40: Log | B40: LOGG3 | C40: Exploração de imóveis | D40: 86999140 | E40: =D40*P40 -> 2289817365 | F40: 300000000 | G40: =P40/L40 -> 7.6327245 | H40: 8.6 | I40: =(G40/H40-1) -> -0.11247389 | J40: 0.2197 | K40: 0.7 | L40: =F40/D40 -> 3.4483099 | M40: 0.63 | N40: =M40*L40 -> 2.1724353 | O40: =N40/P40 -> 0.082539334 | P40: =IFERROR(__xludf.DUMMYFUNCTION("GOOGLEFINANCE(""BVMF:LOGG3"")"),26.32) -> 26.32 | Q40: 28.64 | R40: =1-(P40/Q40) -> 0.081005587 | S40: Trimestral | T40: fev maio ago e nov | U40: 46091
A41: MDias Branco | B41: MDIA3 | C41: Alimentos | D41: 335383253 | E41: =D41*P41 -> 7354954738 | F41: 800000000 | G41: =P41/L41 -> 9.1936934 | H41: 17.5 | I41: =(G41/H41-1) -> -0.47464609 | J41: 0.055 | K41: -0.5 | L41: =F41/D41 -> 2.3853308 | M41: 0.8 | N41: =M41*L41 -> 1.9082646 | O41: =N41/P41 -> 0.087016171 | P41: =IFERROR(__xludf.DUMMYFUNCTION("GOOGLEFINANCE(""BVMF:MDIA3"")"),21.93) -> 21.93 | Q41: =N41/0.08 -> 23.853308 | R41: =1-(P41/Q41) -> 0.080630658 | S41: Mensal | T41: jan a dezembro | U41: 46091
...

Sheet Preço teto Bazin adaptado
A1: Vídeo da planilha: | B1: PLANILHA para os MEMBROS: QUAIS AS DIFERENÇAS? E FORMAS DE UTILIZAR
A3: Empresa | B3: Código | C3: Atuação | D3: Quantidade total de ações | E3: Valor de mercado | F3: Lucro líquido estimado | G3: P/L projetado | H3: P/L médio (últ. 10 anos) | I3: Desvio do P/L da sua média | J3: CAGR lucros (últ. 5 anos) | K3: Dívida líquida/EBITDA | L3: Lucro por ação estimado | M3: Payout esperado | N3: Dividendo por ação bruto projetado | O3: Dividend Yield bruto estimado | P3: Cotação atual | Q3: Preço Teto baseado em 7,55% de yield (Taxa do Tesouro IPCA+ 2037 com juros semestrais) | R3: Margem de segurança | S3: Frequência nos anúncios | T3: Meses que costumam anunciar dividendos | U3: Última atualização
A4: Allos | B4: ALOS3 | C4: Shoppings | D4: 499180780 | E4: =D4*P4 -> 14436308158 | F4: 1500000000 | G4: =P4/L4 -> 9.6242054 | H4: 14.4 | I4: =(G4/H4-1) -> -0.3316524 | J4: 0.365 | K4: 1.8 | L4: =F4/D4 -> 3.0049234 | M4: 1.158 | N4: =M4*L4 -> 3.4797013 | O4: =N4/P4 -> 0.12032162 | P4: =IFERROR(__xludf.DUMMYFUNCTION("GOOGLEFINANCE(""BVMF:ALOS3"")"),28.92) -> 28.92 | Q4: =N4/0.0755 -> 46.088759 | R4: =1-(P4/Q4) -> 0.3725151 | S4: Mensal | T4: jan-dez | U4: 46091
A5: Stone | B5: STOC34 | C5: Serviços Financeiros | D5: 248904657 | E5: =D5*P5 -> 18244711358 | F5: 2760000000 | G5: =P5/L5 -> 6.6104027 | H5: 21.4 | I5: =(G5/H5-1) -> -0.69110268 | J5: 0.1 | K5: 0 | L5: =F5/D5 -> 11.088583 | M5: 0.7 | N5: =M5*L5 -> 7.7620082 | O5: =N5/P5 -> 0.1058937 | P5: =IFERROR(__xludf.DUMMYFUNCTION("GOOGLEFINANCE(""BVMF:STOC34"")"),73.3) -> 73.3 | Q5: =N5/0.0755 -> 102.80806 | R5: =1-(P5/Q5) -> 0.28702086 | S5: Indefinido | T5: Indefinido | U5: 46094
A6: BB Seguridade | B6: BBSE3 | C6: Seguros | D6: 1941214909 | E6: =D6*P6 -> 68039582560 | F6: 8100000000 | G6: =P6/L6 -> 8.3999485 | H6: 12.1 | I6: =(G6/H6-1) -> -0.30578938 | J6: 0.183 | K6: 0 | L6: =F6/D6 -> 4.1726446 | M6: 0.88 | N6: =M6*L6 -> 3.6719273 | O6: =N6/P6 -> 0.10476255 | P6: =IFERROR(__xludf.DUMMYFUNCTION("GOOGLEFINANCE(""BVMF:BBSE3"")"),35.05) -> 35.05 | Q6: =N6/0.0755 -> 48.634799 | R6: =1-(P6/Q6) -> 0.2793226 | S6: Semestral | T6: fevereiro e agosto | U6: 46091
A7: Banco BMG | B7: BMGB4 | C7: Bancos | D7: 631845354 | E7: =D7*P7 -> 2988628524 | F7: 600000000 | G7: =P7/L7 -> 4.9810475 | H7: 8.3 | I7: =(G7/H7-1) -> -0.39987379 | J7: 0.0026 | K7: 0 | L7: =F7/D7 -> 0.94959945 | M7: 0.5 | N7: =M7*L7 -> 0.47479972 | O7: =N7/P7 -> 0.10038049 | P7: =IFERROR(__xludf.DUMMYFUNCTION("GOOGLEFINANCE(""BVMF:BMGB4"")"),4.73) -> 4.73 | Q7: =N7/0.0755 -> 6.2887381 | R7: =1-(P7/Q7) -> 0.24786182 | S7: Trimestral | T7: abr jul out e dez | U7: 46091
A8: JHSF | B8: JHSF3 | C8: Imobiliário | D8: 658316448 | E8: =D8*P8 -> 5661521453 | F8: 600000000 | G8: =P8/L8 -> 9.4358691 | H8: 5.4 | I8: =(G8/H8-1) -> 0.74738316 | J8: 0.1529 | K8: 1.86 | L8: =F8/D8 -> 0.91141578 | M8: 0.9 | N8: =M8*L8 -> 0.8202742 | O8: =N8/P8 -> 0.095380721 | P8: =IFERROR(__xludf.DUMMYFUNCTION("GOOGLEFINANCE(""BVMF:JHSF3"")"),8.6) -> 8.6 | Q8: =N8/0.0755 -> 10.864559 | R8: =1-(P8/Q8) -> 0.20843543 | S8: Mensal | T8: jan a dezembro | U8: 46091
A9: Marcopolo | B9: POMO3 | C9: Industrial | D9: 1241439543 | E9: =D9*P9 -> 6852746277 | F9: 1300000000 | G9: =P9/L9 -> 5.2713433 | H9: 10.8 | I9: =(G9/H9-1) -> -0.51191266 | J9: 0.682 | K9: 0.85 | L9: =F9/D9 -> 1.0471714 | M9: 0.5 | N9: =M9*L9 -> 0.52358571 | O9: =N9/P9 -> 0.094852483 | P9: =IFERROR(__xludf.DUMMYFUNCTION("GOOGLEFINANCE(""BVMF:POMO3"")"),5.52) -> 5.52 | Q9: =N9/0.0755 -> 6.93491 | R9: =1-(P9/Q9) -> 0.20402716 | S9: Trimestral | T9: fev mai ago e nov | U9: 46091
A10: Banco Banrisul | B10: BRSR6 | C10: Bancos | D10: 408974000 | E10: =D10*P10 -> 6919840080 | F10: 1400000000 | G10: =P10/L10 -> 4.9427429 | H10: 6.5 | I10: =(G10/H10-1) -> -0.23957801 | J10: 0.011 | K10: 0 | L10: =F10/D10 -> 3.4232005 | M10: 0.45 | N10: =M10*L10 -> 1.5404402 | O10: =N10/P10 -> 0.091042566 | P10: =IFERROR(__xludf.DUMMYFUNCTION("GOOGLEFINANCE(""BVMF:BRSR6"")"),16.92) -> 16.92 | Q10: =N10/0.0755 -> 20.403182 | R10: =1-(P10/Q10) -> 0.17071758 | S10: Trimestral | T10: Mar, jun, set, dez | U10: 46091
A11: Marcopolo | B11: POMO4 | C11: Industrial | D11: 1241439543 | E11: =D11*P11 -> 7312078908 | F11: 1300000000 | G11: =P11/L11 -> 5.6246761 | H11: 9.7 | I11: =(G11/H11-1) -> -0.42013649 | J11: 0.682 | K11: 0.85 | L11: =F11/D11 -> 1.0471714 | M11: 0.5 | N11: =M11*L11 -> 0.52358571 | O11: =N11/P11 -> 0.088894008 | P11: =IFERROR(__xludf.DUMMYFUNCTION("GOOGLEFINANCE(""BVMF:POMO4"")"),5.89) -> 5.89 | Q11: =N11/0.0755 -> 6.93491 | R11: =1-(P11/Q11) -> 0.15067391 | S11: Trimestral | T11: fev mai ago e nov | U11: 46091
A12: Mahle Metal Leve | B12: LEVE3 | C12: Automóveis e Motocicletas | D12: 135539000 | E12: =D12*P12 -> 4667963160 | F12: 630000000 | G12: =P12/L12 -> 7.4094653 | H12: 11.2 | I12: =(G12/H12-1) -> -0.3384406 | J12: 0.345 | K12: 0.87 | L12: =F12/D12 -> 4.6481087 | M12: 0.65 | N12: =M12*L12 -> 3.0212706 | O12: =N12/P12 -> 0.087725628 | P12: =IFERROR(__xludf.DUMMYFUNCTION("GOOGLEFINANCE(""BVMF:LEVE3"")"),34.44) -> 34.44 | Q12: =N12/0.0755 -> 40.01683 | R12: =1-(P12/Q12) -> 0.1393621 | S12: Semestral | T12: abril e nov | U12: 46091
A13: Banco ABC Brasil | B13: ABCB4 | C13: Bancos | D13: 244657000 | E13: =D13*P13 -> 6295024610 | F13: 1100000000 | G13: =P13/L13 -> 5.7227496 | H13: 6.7 | I13: =(G13/H13-1) -> -0.14585826 | J13: 0.275 | K13: 0 | L13: =F13/D13 -> 4.4960904 | M13: 0.5 | N13: =M13*L13 -> 2.2480452 | O13: =N13/P13 -> 0.087370588 | P13: =IFERROR(__xludf.DUMMYFUNCTION("GOOGLEFINANCE(""BVMF:ABCB4"")"),25.73) -> 25.73 | Q13: =N13/0.0755 -> 29.775433 | R13: =1-(P13/Q13) -> 0.1358648 | S13: Semestral | T13: junho e dez | U13: 46091
A14: Mdias Branco | B14: MDIA3 | C14: Alimentos | D14: 335383253 | E14: =D14*P14 -> 7354954738 | F14: 800000000 | G14: =P14/L14 -> 9.1936934 | H14: 17.5 | I14: =(G14/H14-1) -> -0.47464609 | J14: 0.055 | K14: -0.5 | L14: =F14/D14 -> 2.3853308 | M14: 0.8 | N14: =M14*L14 -> 1.9082646 | O14: =N14/P14 -> 0.087016171 | P14: =IFERROR(__xludf.DUMMYFUNCTION("GOOGLEFINANCE(""BVMF:MDIA3"")"),21.93) -> 21.93 | Q14: =N14/0.0755 -> 25.275028 | R14: =1-(P14/Q14) -> 0.13234518 | S14: Mensal | T14: jan a dezembro | U14: 46091
A15: Pagbank | B15: PAGS34 | C15: Bancos | D15: =279705823*5 -> 1398529115 | E15: =D15*P15 -> 13831452947 | F15: 2550000000 | G15: =P15/L15 -> 5.4240992 | H15: 21.4 | I15: =(G15/H15-1) -> -0.74653742 | J15: 0.158 | K15: 0 | L15: =F15/D15 -> 1.8233442 | M15: 0.4714 | N15: =M15*L15 -> 0.85952447 | O15: =N15/P15 -> 0.08690844 | P15: =IFERROR(__xludf.DUMMYFUNCTION("GOOGLEFINANCE(""BVMF:PAGS34"")"),9.89) -> 9.89 | Q15: =N15/0.0755 -> 11.38443 | R15: =1-(P15/Q15) -> 0.13126965 | S15: Trimestral | T15: fev jun set e dez | U15: 46091
A16: Bradespar | B16: BRAP4 | C16: Holding | D16: 393097000 | E16: =D16*P16 -> 8687443700 | F16: 1670000000 | G16: =P16/L16 -> 5.2020621 | H16: 8.7 | I16: =(G16/H16-1) -> -0.40206183 | J16: -0.059 | K16: -0.64 | L16: =F16/D16 -> 4.2483153 | M16: 0.45 | N16: =M16*L16 -> 1.9117419 | O16: =N16/P16 -> 0.086504158 | P16: =IFERROR(__xludf.DUMMYFUNCTION("GOOGLEFINANCE(""BVMF:BRAP4"")"),22.1) -> 22.1 | Q16: =N16/0.0755 -> 25.321085 | R16: =1-(P16/Q16) -> 0.12720958 | S16: Semestral | T16: abril e novembro | U16: 46091
A17: BR Partners | B17: BRBI11 | C17: Serviços Financeiros | D17: =314987000/3 -> 1.0499567e+08 | E17: =D17*P17 -> 1974968490 | F17: 210000000 | G17: =P17/L17 -> 9.4046119 | H17: 9.1 | I17: =(G17/H17-1) -> 0.03347383 | J17: 0.2 | K17: 0 | L17: =F17/D17 -> 2.0000825 | M17: 0.8 | N17: =M17*L17 -> 1.600066 | O17: =N17/P17 -> 0.085064648 | P17: =IFERROR(__xludf.DUMMYFUNCTION("GOOGLEFINANCE(""BVMF:BRBI11"")"),18.81) -> 18.81 | Q17: =N17/0.0755 -> 21.192928 | R17: =1-(P17/Q17) -> 0.11243976 | S17: Trimestral | T17: mar maio ago e nov | U17: 46091
A18: Tegma | B18: TGMA3 | C18: Logistica | D18: 66003000 | E18: =D18*P18 -> 2075794350 | F18: 220000000 | G18: =P18/L18 -> 9.4354289 | H18: 12.9 | I18: =(G18/H18-1) -> -0.26857141 | J18: 0.307 | K18: -0.35 | L18: =F18/D18 -> 3.3331818 | M18: 0.8 | N18: =M18*L18 -> 2.6665455 | O18: =N18/P18 -> 0.084786819 | P18: =IFERROR(__xludf.DUMMYFUNCTION("GOOGLEFINANCE(""BVMF:TGMA3"")"),31.45) -> 31.45 | Q18: =N18/0.0755 -> 35.318483 | R18: =1-(P18/Q18) -> 0.1095314 | S18: Quadrimestral | T18: abr ago e nov | U18: 46091
A19: Taesa | B19: TAEE3 | C19: Energia | D19: 1033496721 | E19: =D19*P19 -> 14313929586 | F19: 1270000000 | G19: =P19/L19 -> 11.270811 | H19: 8.6 | I19: =(G19/H19-1) -> 0.31055938 | J19: -0.058 | K19: 4.1 | L19: =F19/D19 -> 1.228838 | M19: 0.95 | N19: =M19*L19 -> 1.1673961 | O19: =N19/P19 -> 0.084288524 | P19: =IFERROR(__xludf.DUMMYFUNCTION("GOOGLEFINANCE(""BVMF:TAEE3"")"),13.85) -> 13.85 | Q19: =N19/0.0755 -> 15.462199 | R19: =1-(P19/Q19) -> 0.10426715 | S19: Trimestral | T19: mai, ago, nov, dez | U19: 46091
A20: Tim | B20: TIMS3 | C20: Telecomunicações | D20: 2420598680 | E20: =D20*P20 -> 64387924888 | F20: 5400000000 | G20: =P20/L20 -> 11.92369 | H20: 14.8 | I20: =(G20/H20-1) -> -0.19434528 | J20: 0.145 | K20: -0.18 | L20: =F20/D20 -> 2.2308531 | M20: 1 | N20: =M20*L20 -> 2.2308531 | O20: =N20/P20 -> 0.083866657 | P20: =IFERROR(__xludf.DUMMYFUNCTION("GOOGLEFINANCE(""BVMF:TIMS3"")"),26.6) -> 26.6 | Q20: =N20/0.0755 -> 29.547723 | R20: =1-(P20/Q20) -> 0.099761421 | S20: 5x por ano | T20: mar abr jun set dez | U20: 46091
A21: Banco Banese | B21: BGIP4 | C21: Bancos | D21: 21548228 | E21: =D21*P21 -> 8.1085982e+08 | F21: 150000000 | G21: =P21/L21 -> 5.4057321 | H21: 7.3 | I21: =(G21/H21-1) -> -0.25948875 | J21: 0.22 | K21: 0 | L21: =F21/D21 -> 6.9611292 | M21: 0.45 | N21: =M21*L21 -> 3.1325082 | O21: =N21/P21 -> 0.083244968 | P21: =IFERROR(__xludf.DUMMYFUNCTION("GOOGLEFINANCE(""BVMF:BGIP4"")"),37.63) -> 37.63 | Q21: =N21/0.0755 -> 41.490174 | R21: =1-(P21/Q21) -> 0.093038276 | S21: Trimestral | T21: fev maio ago e nov | U21: 46091
A22: Taesa | B22: TAEE11 | C22: Energia | D22: =1033496721/3 -> 344498907 | E22: =D22*P22 -> 14537853875 | F22: 1270000000 | G22: =P22/L22 -> 11.447129 | H22: 8.6 | I22: =(G22/H22-1) -> 0.33106152 | J22: -0.058 | K22: 4.1 | L22: =F22/D22 -> 3.6865139 | M22: 0.95 | N22: =M22*L22 -> 3.5021882 | O22: =N22/P22 -> 0.082990241 | P22: =IFERROR(__xludf.DUMMYFUNCTION("GOOGLEFINANCE(""BVMF:TAEE11"")"),42.2) -> 42.2 | Q22: =N22/0.0755 -> 46.386598 | R22: =1-(P22/Q22) -> 0.090254482 | S22: Trimestral | T22: mai, ago, nov, dez | U22: 46091
A23: Log | B23: LOGG3 | C23: Exploração de imóveis | D23: 86999140 | E23: =D23*P23 -> 2289817365 | F23: 300000000 | G23: =P23/L23 -> 7.6327245 | H23: 8.6 | I23: =(G23/H23-1) -> -0.11247389 | J23: 0.2197 | K23: 0.7 | L23: =F23/D23 -> 3.4483099 | M23: 0.63 | N23: =M23*L23 -> 2.1724353 | O23: =N23/P23 -> 0.082539334 | P23: =IFERROR(__xludf.DUMMYFUNCTION("GOOGLEFINANCE(""BVMF:LOGG3"")"),26.32) -> 26.32 | Q23: =N23/0.0755 -> 28.773977 | R23: =1-(P23/Q23) -> 0.085284598 | S23: Trimestral | T23: fev maio ago e nov | U23: 46091
A24: Taesa | B24: TAEE4 | C24: Energia | D24: 1033496721 | E24: =D24*P24 -> 14644648537 | F24: 1270000000 | G24: =P24/L24 -> 11.531219 | H24: 8.6 | I24: =(G24/H24-1) -> 0.34083946 | J24: -0.058 | K24: 4.1 | L24: =F24/D24 -> 1.228838 | M24: 0.95 | N24: =M24*L24 -> 1.1673961 | O24: =N24/P24 -> 0.082385043 | P24: =IFERROR(__xludf.DUMMYFUNCTION("GOOGLEFINANCE(""BVMF:TAEE4"")"),14.17) -> 14.17 | Q24: =N24/0.0755 -> 15.462199 | R24: =1-(P24/Q24) -> 0.083571517 | S24: Trimestral | T24: mai, ago, nov, dez | U24: 46091
A25: Vale | B25: VALE3 | C25: Mineração | D25: 4437636744 | E25: =D25*P25 -> 347466957055 | F25: 53000000000 | G25: =P25/L25 -> 6.5559803 | H25: 10.3 | I25: =(G25/H25-1) -> -0.36349706 | J25: 0.023 | K25: 0.99 | L25: =F25/D25 -> 11.943294 | M25: 0.53 | N25: =M25*L25 -> 6.3299458 | O25: =N25/P25 -> 0.080842219 | P25: =IFERROR(__xludf.DUMMYFUNCTION("GOOGLEFINANCE(""BVMF:VALE3"")"),78.3) -> 78.3 | Q25: =N25/0.0755 -> 83.840342 | R25: =1-(P25/Q25) -> 0.066082049 | S25: Quadrimestral | T25: mar, ago e dez | U25: 46091
A26: Grendene | B26: GRND3 | C26: Calçados | D26: 902160000 | E26: =D26*P26 -> 4095806400 | F26: 600000000 | G26: =P26/L26 -> 6.826344 | H26: 10.9 | I26: =(G26/H26-1) -> -0.37372991 | J26: 0.149 | K26: -2.38 | L26: =F26/D26 -> 0.6650705 | M26: 0.55 | N26: =M26*L26 -> 0.36578877 | O26: =N26/P26 -> 0.080570214 | P26: =IFERROR(__xludf.DUMMYFUNCTION("GOOGLEFINANCE(""BVMF:GRND3"")"),4.54) -> 4.54 | Q26: =N26/0.0755 -> 4.8448844 | R26: =1-(P26/Q26) -> 0.062929142 | S26: Quadrimestral | T26: maio ago e nov | U26: 46091
A27: Banco Bradesco | B27: BBDC3 | C27: Bancos | D27: 10597012700 | E27: =D27*P27 -> 174002948534 | F27: 28000000000 | G27: =P27/L27 -> 6.214391 | H27: 9.2 | I27: =(G27/H27-1) -> -0.32452272 | J27: 0.0485 | K27: 0 | L27: =F27/D27 -> 2.6422541 | M27: 0.5 | N27: =M27*L27 -> 1.321127 | O27: =N27/P27 -> 0.080458407 | P27: =IFERROR(__xludf.DUMMYFUNCTION("GOOGLEFINANCE(""BVMF:BBDC3"")"),16.42) -> 16.42 | Q27: =N27/0.0755 -> 17.498371 | R27: =1-(P27/Q27) -> 0.061626956 | S27: Semestral | T27: junho e dez | U27: 46091
A28: Banco Itau | B28: ITUB3 | C28: Bancos | D28: 10753776126 | E28: =D28*P28 -> 441227434450 | F28: 50000000000 | G28: =P28/L28 -> 8.8245487 | H28: 9.1 | I28: =(G28/H28-1) -> -0.030269375 | J28: 0.238 | K28: 0 | L28: =F28/D28 -> 4.6495296 | M28: 0.7 | N28: =M28*L28 -> 3.2546707 | O28: =N28/P28 -> 0.07932417 | P28: =IFERROR(__xludf.DUMMYFUNCTION("GOOGLEFINANCE(""BVMF:ITUB3"")"),41.03) -> 41.03 | Q28: =N28/0.0755 -> 43.108221 | R28: =1-(P28/Q28) -> 0.048209391 | S28: Semestral | T28: fevereiro e ago | U28: 46091
A29: Itausa | B29: ITSA4 | C29: Holding | D29: 11213700000 | E29: =D29*P29 -> 147572292000 | F29: 17900000000 | G29: =P29/L29 -> 8.2442621 | H29: 8.7 | I29: =(G29/H29-1) -> -0.052383664 | J29: 0.164 | K29: 0 | L29: =F29/D29 -> 1.5962617 | M29: 0.65 | N29: =M29*L29 -> 1.0375701 | O29: =N29/P29 -> 0.078842714 | P29: =IFERROR(__xludf.DUMMYFUNCTION("GOOGLEFINANCE(""BVMF:ITSA4"")"),13.16) -> 13.16 | Q29: =N29/0.0755 -> 13.742651 | R29: =1-(P29/Q29) -> 0.042397246 | S29: Semestral | T29: fevereiro e ago | U29: 46091
A30: Odontoprev | B30: ODPV3 | C30: Seguros | D30: 545092900 | E30: =D30*P30 -> 7195226280 | F30: 595000000 | G30: =P30/L30 -> 12.092817 | H30: 19.4 | I30: =(G30/H30-1) -> -0.3766589 | J30: 0.1 | K30: -0.64 | L30: =F30/D30 -> 1.0915571 | M30: 0.95 | N30: =M30*L30 -> 1.0369792 | O30: =N30/P30 -> 0.07855903 | P30: =IFERROR(__xludf.DUMMYFUNCTION("GOOGLEFINANCE(""BVMF:ODPV3"")"),13.2) -> 13.2 | Q30: =N30/0.0755 -> 13.734824 | R30: =1-(P30/Q30) -> 0.038939258 | S30: 8x por ano | T30: mar abr mai jun ago set nov dez | U30: 46091
A31: Banco Santander | B31: SANB3 | C31: Bancos | D31: 7470968456 | E31: =D31*P31 -> 111915107471 | F31: 17400000000 | G31: =P31/L31 -> 6.4319027 | H31: 10.2 | I31: =(G31/H31-1) -> -0.3694213 | J31: -0.015 | K31: 0 | L31: =F31/D31 -> 2.3290153 | M31: 0.5 | N31: =M31*L31 -> 1.1645077 | O31: =N31/P31 -> 0.077737494 | P31: =IFERROR(__xludf.DUMMYFUNCTION("GOOGLEFINANCE(""BVMF:SANB3"")"),14.98) -> 14.98 | Q31: =N31/0.0755 -> 15.423943 | R31: =1-(P31/Q31) -> 0.028782688 | S31: Trimestral | T31: fev, abr, julho e out | U31: 46091
A32: Caixa Seguridade | B32: CXSE3 | C32: Seguros | D32: 3000000000 | E32: =D32*P32 -> 54420000000 | F32: 4700000000 | G32: =P32/L32 -> 11.578723 | H32: 12.4 | I32: =(G32/H32-1) -> -0.066231984 | J32: 0.197 | K32: 0 | L32: =F32/D32 -> 1.5666667 | M32: 0.9 | N32: =M32*L32 -> 1.41 | O32: =N32/P32 -> 0.077728776 | P32: =IFERROR(__xludf.DUMMYFUNCTION("GOOGLEFINANCE(""BVMF:CXSE3"")"),18.14) -> 18.14 | Q32: =N32/0.0755 -> 18.675497 | R32: =1-(P32/Q32) -> 0.028673759 | S32: Trimestral | T32: jan, abr, ago e nov | U32: 46091
A33: CPFL Energia | B33: CPFE3 | C33: Energia | D33: 1152254440 | E33: =D33*P33 -> 55481051286 | F33: 5500000000 | G33: =P33/L33 -> 10.087464 | H33: 13 | I33: =(G33/H33-1) -> -0.22404124 | J33: 0.087 | K33: 2.07 | L33: =F33/D33 -> 4.7732513 | M33: 0.781 | N33: =M33*L33 -> 3.7279093 | O33: =N33/P33 -> 0.07742283 | P33: =IFERROR(__xludf.DUMMYFUNCTION("GOOGLEFINANCE(""BVMF:CPFE3"")"),48.15) -> 48.15 | Q33: =N33/0.0755 -> 49.376282 | R33: =1-(P33/Q33) -> 0.024835439 | S33: Semestral | T33: abril e agosto | U33: 46091
A34: Banco Santander | B34: SANB11 | C34: Bancos | D34: =7470968456/2 -> 3735484228 | E34: =D34*P34 -> 112886333370 | F34: 17400000000 | G34: =P34/L34 -> 6.4877203 | H34: 10.2 | I34: =(G34/H34-1) -> -0.36394899 | J34: -0.015 | K34: 0 | L34: =F34/D34 -> 4.6580306 | M34: 0.5 | N34: =M34*L34 -> 2.3290153 | O34: =N34/P34 -> 0.077068674 | P34: =IFERROR(__xludf.DUMMYFUNCTION("GOOGLEFINANCE(""BVMF:SANB11"")"),30.22) -> 30.22 | Q34: =N34/0.0755 -> 30.847885 | R34: =1-(P34/Q34) -> 0.020354233 | S34: Trimestral | T34: fev, abr, julho e out | U34: 46091
A35: Grazziotin | B35: CGRA4 | C35: Varejo | D35: 23601907 | E35: =D35*P35 -> 6.5282875e+08 | F35: 100000000 | G35: =P35/L35 -> 6.5282875 | H35: 7.3 | I35: =(G35/H35-1) -> -0.10571404 | J35: 0.078 | K35: -1.63 | L35: =F35/D35 -> 4.2369458 | M35: 0.5 | N35: =M35*L35 -> 2.1184729 | O35: =N35/P35 -> 0.076589764 | P35: =IFERROR(__xludf.DUMMYFUNCTION("GOOGLEFINANCE(""BVMF:CGRA4"")"),27.66) -> 27.66 | Q35: =N35/0.0755 -> 28.059244 | R35: =1-(P35/Q35) -> 0.014228591 | S35: Semestral | T35: jun e dez | U35: 46091
A36: CEB | B36: CEBR6 | C36: Energia | D36: 72082000 | E36: =D36*P36 -> 2235983640 | F36: 200000000 | G36: =P36/L36 -> 11.179918 | H36: 7.1 | I36: =(G36/H36-1) -> 0.57463637 | J36: 0.073 | K36: -3.17 | L36: =F36/D36 -> 2.7746178 | M36: 0.778 | N36: =M36*L36*1.1 -> 2.3745179 | O36: =N36/P36 -> 0.076547966 | P36: =IFERROR(__xludf.DUMMYFUNCTION("GOOGLEFINANCE(""BVMF:CEBR6"")"),31.02) -> 31.02 | Q36: =N36/0.0755 -> 31.450568 | R36: =1-(P36/Q36) -> 0.01369032 | S36: Semestral | T36: Abril e novembro | U36: 46091
A37: Banco Bradesco | B37: BBDC4 | C37: Bancos | D37: 10597012700 | E37: =D37*P37 -> 201237271173 | F37: 28000000000 | G37: =P37/L37 -> 7.1870454 | H37: 10.1 | I37: =(G37/H37-1) -> -0.28841135 | J37: 0.0118 | K37: 0 | L37: =F37/D37 -> 2.6422541 | M37: 0.55 | N37: =M37*L37 -> 1.4532397 | O37: =N37/P37 -> 0.076526579 | P37: =IFERROR(__xludf.DUMMYFUNCTION("GOOGLEFINANCE(""BVMF:BBDC4"")"),18.99) -> 18.99 | Q37: =N37/0.0755 -> 19.248209 | R37: =1-(P37/Q37) -> 0.013414677 | S37: Semestral | T37: junho e dez | U37: 46091
A38: Banco Santander | B38: SANB4 | C38: Bancos | D38: 7470968456 | E38: =D38*P38 -> 114604656115 | F38: 17400000000 | G38: =P38/L38 -> 6.5864745 | H38: 10.2 | I38: =(G38/H38-1) -> -0.35426721 | J38: -0.015 | K38: 0 | L38: =F38/D38 -> 2.3290153 | M38: 0.5 | N38: =M38*L38 -> 1.1645077 | O38: =N38/P38 -> 0.075913146 | P38: =IFERROR(__xludf.DUMMYFUNCTION("GOOGLEFINANCE(""BVMF:SANB4"")"),15.34) -> 15.34 | Q38: =N38/0.0755 -> 15.423943 | R38: =1-(P38/Q38) -> 0.0054423521 | S38: Trimestral | T38: fev, abr, julho e out | U38: 46091
A39: CSU | B39: CSUD3 | C39: Tecnologia | D39: 41280684 | E39: =D39*P39 -> 7.5956459e+08 | F39: 115000000 | G39: =P39/L39 -> 6.6049094 | H39: 10.1 | I39: =(G39/H39-1) -> -0.34604857 | J39: 0.147 | K39: -0.13 | L39: =F39/D39 -> 2.7858066 | M39: 0.5 | N39: =M39*L39 -> 1.3929033 | O39: =N39/P39 -> 0.075701265 | P39: =IFERROR(__xludf.DUMMYFUNCTION("GOOGLEFINANCE(""BVMF:CSUD3"")"),18.4) -> 18.4 | Q39: =N39/0.0755 -> 18.44905 | R39: =1-(P39/Q39) -> 0.0026586746 | S39: Trimestral | T39: mar abr jun set e dez | U39: 46091
A40: Irani | B40: RANI3 | C40: Papel e Celulose | D40: 221172300 | E40: =D40*P40 -> 2012667930 | F40: 215000000 | G40: =P40/L40 -> 9.3612462 | H40: 9.4 | I40: =(G40/H40-1) -> -0.0041227462 | J40: 0.33 | K40: 2.06 | L40: =F40/D40 -> 0.9720928 | M40: 0.7 | N40: =M40*L40 -> 0.68046496 | O40: =N40/P40 -> 0.074776369 | P40: =IFERROR(__xludf.DUMMYFUNCTION("GOOGLEFINANCE(""BVMF:RANI3"")"),9.1) -> 9.1 | Q40: =N40/0.0755 -> 9.0127809 | R40: =1-(P40/Q40) -> -0.0096772672 | S40: 5x por ano | T40: mar abr mai ago nov | U40: 46091
A41: CEB | B41: CEBR5 | C41: Energia | D41: 72082000 | E41: =D41*P41 -> 2100469480 | F41: 200000000 | G41: =P41/L41 -> 10.502347 | H41: 7.1 | I41: =(G41/H41-1) -> 0.47920386 | J41: 0.073 | K41: -3.17 | L41: =F41/D41 -> 2.7746178 | M41: 0.778 | N41: =M41*L41 -> 2.1586526 | O41: =N41/P41 -> 0.074078677 | P41: =IFERROR(__xludf.DUMMYFUNCTION("GOOGLEFINANCE(""BVMF:CEBR5"")"),29.14) -> 29.14 | Q41: =N41/0.0755 -> 28.591426 | R41: =1-(P41/Q41) -> -0.019186669 | S41: Semestral | T41: Abril e novembro | U41: 46091
...

Sheet Renda projetiva
A1: Vídeo da planilha: | B1: PLANILHA para os MEMBROS: QUAIS AS DIFERENÇAS? E FORMAS DE UTILIZAR
A3: Ticker | B3: Qtd. de ações | C3: Dividendo por ação | D3: Renda anual esperada | E3: Capital alocado | F3: Dividend Yield | H3: Ano | I3: Renda Anual | J3: Renda Mensal | K3: Taxa de crescimento (vs ano anterior)
A4: CEBR5 | B4: 34000 | C4: =VLOOKUP(A4,Dados!B2:Q105,13,FALSE) -> 2.1586526 | D4: =B4*C4 -> 73394.19 | E4: =VLOOKUP(A4,Dados!B2:R105,15,FALSE)*B4 -> 990760 | F4: =D4/E4 -> 0.074078677 | H4: 2026 | I4: =D22 -> 277237.22 | J4: =I4/12 -> 23103.102
A5: BBSE3 | B5: 13100 | C5: =VLOOKUP(A5,Dados!B2:Q105,13,FALSE) -> 3.9212557 | D5: =B5*C5 -> 51368.449 | E5: =VLOOKUP(A5,Dados!B2:R105,15,FALSE)*B5 -> 459155 | F5: =D5/E5 -> 0.11187605 | H5: 2027 | I5: =I4*(1+K5) -> 346546.53 | J5: =I5/12 -> 28878.877 | K5: 0.25
A6: EMAE4 | B6: 14700 | C6: =VLOOKUP(A6,Dados!B2:Q105,13,FALSE) -> 2.1652638 | D6: =B6*C6 -> 31829.377 | E6: =VLOOKUP(A6,Dados!B2:R105,15,FALSE)*B6 -> 654150 | F6: =D6/E6 -> 0.048657613 | H6: 2028 | I6: =I5*(1+K6) -> 415855.83 | J6: =I6/12 -> 34654.653 | K6: 0.2
A7: BBAS3 | B7: 20000 | C7: =VLOOKUP(A7,Dados!B2:Q105,13,FALSE) -> 1.2612337 | D7: =B7*C7 -> 25224.674 | E7: =VLOOKUP(A7,Dados!B2:R105,15,FALSE)*B7 -> 476200 | F7: =D7/E7 -> 0.052970756 | H7: 2029 | I7: =I6*(1+K7) -> 478234.21 | J7: =I7/12 -> 39852.851 | K7: 0.15
A8: LEVE3 | B8: 6900 | C8: =VLOOKUP(A8,Dados!B2:Q105,13,FALSE) -> 3.0212706 | D8: =B8*C8 -> 20846.767 | E8: =VLOOKUP(A8,Dados!B2:R105,15,FALSE)*B8 -> 237636 | F8: =D8/E8 -> 0.087725628 | H8: 2030 | I8: =I7*(1+K8) -> 549969.34 | J8: =I8/12 -> 45830.778 | K8: 0.15
A9: RANI3 | B9: 21400 | C9: =VLOOKUP(A9,Dados!B2:Q105,13,FALSE) -> 0.68046496 | D9: =B9*C9 -> 14561.95 | E9: =VLOOKUP(A9,Dados!B2:R105,15,FALSE)*B9 -> 194740 | F9: =D9/E9 -> 0.074776369
A10: CEBR6 | B10: 6000 | C10: =VLOOKUP(A10,Dados!B2:Q105,13,FALSE) -> 2.3745179 | D10: =B10*C10 -> 14247.107 | E10: =VLOOKUP(A10,Dados!B2:R105,15,FALSE)*B10 -> 186120 | F10: =D10/E10 -> 0.076547966
A11: CXSE3 | B11: 9200 | C11: =VLOOKUP(A11,Dados!B2:Q105,13,FALSE) -> 1.41 | D11: =B11*C11 -> 12972 | E11: =VLOOKUP(A11,Dados!B2:R105,15,FALSE)*B11 -> 166888 | F11: =D11/E11 -> 0.077728776
A12: CEBR3 | B12: 6000 | C12: =VLOOKUP(A12,Dados!B2:Q105,13,FALSE) -> 2.1586526 | D12: =B12*C12 -> 12951.916 | E12: =VLOOKUP(A12,Dados!B2:R105,15,FALSE)*B12 -> 187200 | F12: =D12/E12 -> 0.069187585
A13: CGAS5 | B13: 1100 | C13: =VLOOKUP(A13,Dados!B2:Q105,13,FALSE) -> 10.262524 | D13: =B13*C13 -> 11288.777 | E13: =VLOOKUP(A13,Dados!B2:R105,15,FALSE)*B13 -> 144980 | F13: =D13/E13 -> 0.077864374
A14: FESA4 | B14: 20700 | C14: =VLOOKUP(A14,Dados!B2:Q105,13,FALSE) -> 0.41314071 | D14: =B14*C14 -> 8552.0126 | E14: =VLOOKUP(A14,Dados!B2:R105,15,FALSE)*B14 -> 153387 | F14: =D14/E14 -> 0.055754481
C22: Renda anual esperada | D22: =SUM(D4:D21) -> 277237.22
C23: Renda média mensal | D23: =D22/12 -> 23103.102
C25: Patrimônio | D25: =SUM(E4:E21) -> 3851216
C26: Dividend Yield esperado | D26: =D22/D25 -> 0.071986931

Sheet Holding
A1: Link do vídeo: | B1: MÁQUINA de GERAR DINHEIRO? VEJA A SUA CARTEIRA COMO UMA HOLDING!
A3: Ticker | B3: Qtd. de ações | C3: Lucro por ação | D3: Lucro anual esperado | E3: Capital alocado | F3: Earning Yield | H3: Ano | I3: Lucro Anual | J3: Lucro médio mensal | K3: Taxa de crescimento (vs ano anterior)
A4: CEBR5 | B4: 34000 | C4: =VLOOKUP(A4,Dados!B2:Q105,11,FALSE) -> 2.7746178 | D4: =B4*C4 -> 94337.005 | E4: =VLOOKUP(A4,Dados!B2:R105,15,FALSE)*B4 -> 990760 | F4: =D4/E4 -> 0.095216808 | H4: 2026 | I4: =D24 -> 442447.49 | J4: =I4/12 -> 36870.624
A5: BBAS3 | B5: 20000 | C5: =VLOOKUP(A5,Dados!B2:Q105,11,FALSE) -> 4.2041124 | D5: =B5*C5 -> 84082.247 | E5: =VLOOKUP(A5,Dados!B2:R105,15,FALSE)*B5 -> 476200 | F5: =D5/E5 -> 0.17656919 | H5: 2027 | I5: =I4*(1+K5) -> 553059.36 | J5: =I5/12 -> 46088.28 | K5: 0.25
A6: EMAE4 | B6: 14700 | C6: =VLOOKUP(A6,Dados!B2:Q105,11,FALSE) -> 5.4131594 | D6: =B6*C6 -> 79573.443 | E6: =VLOOKUP(A6,Dados!B2:R105,15,FALSE)*B6 -> 654150 | F6: =D6/E6 -> 0.12164403 | H6: 2028 | I6: =I5*(1+K6) -> 663671.24 | J6: =I6/12 -> 55305.936 | K6: 0.2
A7: BBSE3 | B7: 13100 | C7: =VLOOKUP(A7,Dados!B2:Q105,11,FALSE) -> 4.4559724 | D7: =B7*C7 -> 58373.238 | E7: =VLOOKUP(A7,Dados!B2:R105,15,FALSE)*B7 -> 459155 | F7: =D7/E7 -> 0.12713188 | H7: 2029 | I7: =I6*(1+K7) -> 763221.92 | J7: =I7/12 -> 63601.827 | K7: 0.15
A8: LEVE3 | B8: 6900 | C8: =VLOOKUP(A8,Dados!B2:Q105,11,FALSE) -> 4.6481087 | D8: =B8*C8 -> 32071.95 | E8: =VLOOKUP(A8,Dados!B2:R105,15,FALSE)*B8 -> 237636 | F8: =D8/E8 -> 0.1349625 | H8: 2030 | I8: =I7*(1+K8) -> 877705.21 | J8: =I8/12 -> 73142.101 | K8: 0.15
A9: RANI3 | B9: 21400 | C9: =VLOOKUP(A9,Dados!B2:Q105,11,FALSE) -> 0.9720928 | D9: =B9*C9 -> 20802.786 | E9: =VLOOKUP(A9,Dados!B2:R105,15,FALSE)*B9 -> 194740 | F9: =D9/E9 -> 0.10682338
A10: CEBR6 | B10: 6000 | C10: =VLOOKUP(A10,Dados!B2:Q105,11,FALSE) -> 2.7746178 | D10: =B10*C10 -> 16647.707 | E10: =VLOOKUP(A10,Dados!B2:R105,15,FALSE)*B10 -> 186120 | F10: =D10/E10 -> 0.089446093
A11: CEBR3 | B11: 6000 | C11: =VLOOKUP(A11,Dados!B2:Q105,11,FALSE) -> 2.7746178 | D11: =B11*C11 -> 16647.707 | E11: =VLOOKUP(A11,Dados!B2:R105,15,FALSE)*B11 -> 187200 | F11: =D11/E11 -> 0.088930058
A12: CXSE3 | B12: 9200 | C12: =VLOOKUP(A12,Dados!B2:Q105,11,FALSE) -> 1.5666667 | D12: =B12*C12 -> 14413.333 | E12: =VLOOKUP(A12,Dados!B2:R105,15,FALSE)*B12 -> 166888 | F12: =D12/E12 -> 0.086365307
A13: CGAS5 | B13: 1100 | C13: =VLOOKUP(A13,Dados!B2:Q105,11,FALSE) -> 12.073558 | D13: =B13*C13 -> 13280.914 | E13: =VLOOKUP(A13,Dados!B2:R105,15,FALSE)*B13 -> 144980 | F13: =D13/E13 -> 0.091605145
A14: FESA4 | B14: 20700 | C14: =VLOOKUP(A14,Dados!B2:Q105,11,FALSE) -> 0.59020101 | D14: =B14*C14 -> 12217.161 | E14: =VLOOKUP(A14,Dados!B2:R105,15,FALSE)*B14 -> 153387 | F14: =D14/E14 -> 0.079649259
C24: Lucro esperado 2026 | D24: =SUM(D4:D23) -> 442447.49
C25: Lucro médio mensal | D25: =D24/12 -> 36870.624
C26: Lucro médio diário | D26: =D24/365 -> 1212.1849
C27: Patrimônio | D27: =SUM(E4:E23) -> 3851216
C28: Earning Yield esperado | D28: =D24/D27 -> 0.11488514

Sheet Calculadoras
A1: Link das Calculadoras
A4: Juros compostos | B4: Calculadora de Juros Compostos - Investidor10
A6: Primeiro milhão | B6: Calculadora do Primeiro Milhão
A8: Vídeo para entender na prática: | B8: ✅ QUANTO TEMPO PARA ATINGIR O PRIMEIRO MILHÃO? QUANTO VOCÊ PRECISARÁ INVESTIR? AÇÕES e INVESTIMENTOS
